Workbook

Sheet Dashboard
A1: SECUREPAY SOLUTIONS PVT. LTD.
A2: GRC RISK & COMPLIANCE DASHBOARD
A3: Framework: ISO/IEC 27001 | Assessment Type: Simulated GRC Assessment | Assessment Period: September 2026
A4: Purpose: Management-level overview of cybersecurity risks, control effectiveness, compliance gaps, and remediation activities.
A6: TOTAL RISKS | C6: CRITICAL RISKS | E6: HIGH RISKS | G6: IMPLEMENTED CONTROLS | I6: PARTIALLY IMPLEMENTED | K6: OPEN REMEDIATIONS
A7: =COUNTA('Risk Register'!A5:A19) -> 15 | C7: =COUNTIF('Risk Register'!J5:J19,"Critical") -> 2 | E7: =COUNTIF('Risk Register'!J5:J19,"High") -> 13 | G7: =COUNTIF('Control Inventory'!G5:G19,"Implemented") -> 7 | I7: =COUNTIF('Control Inventory'!G5:G19,"Partially Implemented") -> 8 | K7: =COUNTIF('Remediation Plan'!H5:H14,"Open") -> 9
A9: RISK & CONTROL OVERVIEW (CHARTS)
A62: COMPLIANCE OVERVIEW
A64: Implemented Control Coverage (project metric — not an official ISO 27001 compliance percentage): | I64: =D184 -> 0.33333333
A65: TOP 5 RISKS REQUIRING ATTENTION
A66: Risk ID | B66: Risk | C66: Score | D66: Rating | E66: Treatment
A67: RSK-001 | B67: =INDEX('Risk Register'!$D$5:$D$19,MATCH(A67,'Risk Register'!$A$5:$A$19,0)) -> Phishing could compromise employee credentials and allow unauthorized system access | C67: =INDEX('Risk Register'!$I$5:$I$19,MATCH(A67,'Risk Register'!$A$5:$A$19,0)) -> 20 | D67: =INDEX('Risk Register'!$J$5:$J$19,MATCH(A67,'Risk Register'!$A$5:$A$19,0)) -> Critical | E67: =INDEX('Risk Register'!$L$5:$L$19,MATCH(A67,'Risk Register'!$A$5:$A$19,0)) -> Mitigate
A68: RSK-010 | B68: =INDEX('Risk Register'!$D$5:$D$19,MATCH(A68,'Risk Register'!$A$5:$A$19,0)) -> Unpatched systems could be exploited by attackers | C68: =INDEX('Risk Register'!$I$5:$I$19,MATCH(A68,'Risk Register'!$A$5:$A$19,0)) -> 20 | D68: =INDEX('Risk Register'!$J$5:$J$19,MATCH(A68,'Risk Register'!$A$5:$A$19,0)) -> Critical | E68: =INDEX('Risk Register'!$L$5:$L$19,MATCH(A68,'Risk Register'!$A$5:$A$19,0)) -> Mitigate
A69: RSK-004 | B69: =INDEX('Risk Register'!$D$5:$D$19,MATCH(A69,'Risk Register'!$A$5:$A$19,0)) -> Ransomware could encrypt business data and disrupt operations | C69: =INDEX('Risk Register'!$I$5:$I$19,MATCH(A69,'Risk Register'!$A$5:$A$19,0)) -> 16 | D69: =INDEX('Risk Register'!$J$5:$J$19,MATCH(A69,'Risk Register'!$A$5:$A$19,0)) -> High | E69: =INDEX('Risk Register'!$L$5:$L$19,MATCH(A69,'Risk Register'!$A$5:$A$19,0)) -> Mitigate
A70: RSK-005 | B70: =INDEX('Risk Register'!$D$5:$D$19,MATCH(A70,'Risk Register'!$A$5:$A$19,0)) -> Weak passwords could allow unauthorized account access | C70: =INDEX('Risk Register'!$I$5:$I$19,MATCH(A70,'Risk Register'!$A$5:$A$19,0)) -> 16 | D70: =INDEX('Risk Register'!$J$5:$J$19,MATCH(A70,'Risk Register'!$A$5:$A$19,0)) -> High | E70: =INDEX('Risk Register'!$L$5:$L$19,MATCH(A70,'Risk Register'!$A$5:$A$19,0)) -> Mitigate
A71: RSK-013 | B71: =INDEX('Risk Register'!$D$5:$D$19,MATCH(A71,'Risk Register'!$A$5:$A$19,0)) -> Email account compromise could enable phishing and data theft | C71: =INDEX('Risk Register'!$I$5:$I$19,MATCH(A71,'Risk Register'!$A$5:$A$19,0)) -> 16 | D71: =INDEX('Risk Register'!$J$5:$J$19,MATCH(A71,'Risk Register'!$A$5:$A$19,0)) -> High | E71: =INDEX('Risk Register'!$L$5:$L$19,MATCH(A71,'Risk Register'!$A$5:$A$19,0)) -> Mitigate
A74: MANAGEMENT SUMMARY
A75: 15 cybersecurity risks were identified across SecurePay's technology environment. Two risks were classified as Critical and thirteen as High based on the likelihood x impact methodology. Key areas requiring attention include identity and access management, vulnerability management, cloud security, endpoint protection, and security monitoring. Several controls are currently only partially implemented. Priority remediation actions include organization-wide MFA implementation, formal vulnerability management, periodic access reviews, improved security monitoring, incident response testing, and endpoint encryption.
A130: SUPPORTING CALCULATIONS (Auto-Generated From Other Sheets)
A132: These values are calculated with formulas referencing the Risk Register, Control Inventory, ISO 27001 Gap Assessment, and Remediation Plan sheets.
A134: Risk Rating Distribution
A135: Risk Rating | B135: Count
A136: Critical | B136: =COUNTIF('Risk Register'!$J$5:$J$19,"Critical") -> 2
A137: High | B137: =COUNTIF('Risk Register'!$J$5:$J$19,"High") -> 13
A138: Medium | B138: =COUNTIF('Risk Register'!$J$5:$J$19,"Medium") -> 0
A139: Low | B139: =COUNTIF('Risk Register'!$J$5:$J$19,"Low") -> 0
A142: Risk Category Distribution
A143: Category | B143: Number of Risks
A144: Access Control | B144: =COUNTIF('Risk Register'!$C$5:$C$19,"Access Control") -> 4
A145: Application Security | B145: =COUNTIF('Risk Register'!$C$5:$C$19,"Application Security") -> 2
A146: Cloud Security | B146: =COUNTIF('Risk Register'!$C$5:$C$19,"Cloud Security") -> 1
A147: Endpoint Security | B147: =COUNTIF('Risk Register'!$C$5:$C$19,"Endpoint Security") -> 2
A148: Data Security | B148: =COUNTIF('Risk Register'!$C$5:$C$19,"Data Security") -> 1
A149: Business Continuity | B149: =COUNTIF('Risk Register'!$C$5:$C$19,"Business Continuity") -> 1
A150: Availability | B150: =COUNTIF('Risk Register'!$C$5:$C$19,"Availability") -> 1
A151: Network Security | B151: =COUNTIF('Risk Register'!$C$5:$C$19,"Network Security") -> 1
A152: Vulnerability Management | B152: =COUNTIF('Risk Register'!$C$5:$C$19,"Vulnerability Management") -> 1
A153: Incident Management | B153: =COUNTIF('Risk Register'!$C$5:$C$19,"Incident Management") -> 1
A156: Control Implementation Status
A157: Control Status | B157: Count
...

Sheet Company Profile
A1: SECUREPAY SOLUTIONS PVT. LTD.
A2: Company & GRC Assessment Profile
A4: 1. ORGANIZATION OVERVIEW
A5: Company Name | B5: SecurePay Solutions Pvt. Ltd.
A6: Organization Type | B6: Private Limited Company
A7: Industry | B7: Financial Technology (FinTech) / Online Payments
A8: Headquarters | B8: Bengaluru, Karnataka, India
A9: Year Established | B9: 2021
A10: Number of Employees | B10: 50
A11: Business Model | B11: B2C and B2B Digital Payment Services
A12: Assessment Type | B12: Internal GRC Risk & Compliance Assessment
A13: Assessment Status | B13: Simulated / Portfolio Project
A14: Assessment Period | B14: September 2026
A15: Primary Framework | B15: ISO/IEC 27001
A16: Supporting Framework | B16: NIST Cybersecurity Framework
... A18: Information Classification | B18: Internal
A20: 2. BUSINESS DESCRIPTION
A21: SecurePay Solutions Pvt. Ltd. is a fictional FinTech organization that provides digital payment services through a customer-facing web application and supporting cloud infrastructure. The platform allows customers and business users to create accounts, manage payment information, initiate transactions, view transaction histories, and receive payment notifications.
A22: The organization relies heavily on information technology and cloud infrastructure to deliver its services. Because the company handles sensitive customer and transaction-related information, maintaining confidentiality, integrity, and availability is considered a key business requirement.
A24: 3. ORGANIZATIONAL STRUCTURE
A25: For the purpose of this assessment, SecurePay has approximately 50 employees.
A26: Department | B26: Approx. Employees | C26: Primary Responsibility
A27: Executive Management | B27: 3 | C27: Business strategy & governance
A28: Information Security | B28: 5 | C28: Security, risk & compliance
A29: IT Infrastructure | B29: 6 | C29: Systems, networks & endpoints
A30: Software Development | B30: 12 | C30: Application development & maintenance
A31: Operations | B31: 8 | C31: Platform & business operations
A32: Customer Support | B32: 8 | C32: Customer assistance
A33: Finance | B33: 5 | C33: Financial operations
A34: Human Resources | B34: 3 | C34: Employee management
A35: Total | B35: 50
A37: 4. KEY BUSINESS FUNCTIONS
A38: • Customer Account Management — Creation and management of customer accounts and profiles.
A39: • Payment Processing — Processing and managing digital payment transactions through the platform.
A40: • Transaction Management — Maintaining transaction records and providing customers with transaction history.
A41: • Application Development — Developing, testing, deploying, and maintaining the SecurePay platform.
A42: • IT Infrastructure Management — Managing cloud infrastructure, networks, endpoints, and supporting systems.
A43: • Security Operations — Monitoring security events, managing vulnerabilities, responding to incidents, and maintaining security controls.
A44: • Customer Support — Handling customer queries, account-related requests, and payment issues.
A45: • Financial Operations — Managing financial reconciliation, reporting, and business transactions.
...

Sheet Asset Inventory
A1: SECUREPAY SOLUTIONS — ASSET INVENTORY
A2: Simulated cybersecurity asset inventory for portfolio purposes.
A4: Asset ID | B4: Asset Name | C4: Asset Type | D4: Description | E4: Owner | F4: Criticality | G4: Confidentiality | H4: Integrity | I4: Availability
A5: AST-001 | B5: Customer Database | C5: Data | D5: Stores customer account and transaction information | E5: Database Admin | F5: Critical | G5: High | H5: High | I5: High
A6: AST-002 | B6: Web Application | C6: Application | D6: Customer-facing online payment platform | E6: Application Owner | F6: Critical | G6: High | H6: High | I6: High
A7: AST-003 | B7: Cloud Infrastructure | C7: Infrastructure | D7: Cloud servers and resources hosting applications | E7: Cloud Admin | F7: Critical | G7: High | H7: High | I7: High
A8: AST-004 | B8: Employee Laptops | C8: Endpoint | D8: Company-issued devices used by employees | E8: IT Admin | F8: High | G8: Medium | H8: High | I8: High
A9: AST-005 | B9: Corporate Email | C9: SaaS | D9: Email communication and business correspondence | E9: IT Admin | F9: High | G9: High | H9: Medium | I9: High
A10: AST-006 | B10: Employee Accounts | C10: Identity | D10: User identities used to access company resources | E10: IAM Admin | F10: Critical | G10: High | H10: High | I10: High
A11: AST-007 | B11: Backup System | C11: Infrastructure | D11: Stores backups of critical systems and data | E11: IT Admin | F11: Critical | G11: High | H11: High | I11: High
A12: AST-008 | B12: Firewall | C12: Network | D12: Filters and controls inbound/outbound traffic | E12: Network Admin | F12: High | G12: Medium | H12: High | I12: High
A13: AST-009 | B13: VPN | C13: Network | D13: Provides secure remote access to internal resources | E13: Network Admin | F13: High | G13: High | H13: High | I13: High
A14: AST-010 | B14: Source Code Repository | C14: Application/Data | D14: Stores application source code and development assets | E14: Development Lead | F14: High | G14: High | H14: High | I14: Medium

Sheet Risk Register
A1: SECUREPAY SOLUTIONS — RISK REGISTER
A2: Simulated cybersecurity risk assessment for portfolio purposes.
A4: Risk ID | B4: Asset | C4: Category | D4: Risk Description | E4: Threat | F4: Vulnerability | G4: Likelihood | H4: Impact | I4: Risk Score | J4: Risk Rating | K4: Existing Control | L4: Treatment | M4: Owner | N4: Status
A5: RSK-001 | B5: Employee Accounts | C5: Access Control | D5: Phishing could compromise employee credentials and allow unauthorized system access | E5: Phishing | F5: Incomplete MFA coverage | G5: 4 | H5: 5 | I5: =G5*H5 -> 20 | J5: =IF(I5>=17,"Critical",IF(I5>=10,"High",IF(I5>=5,"Medium","Low"))) -> Critical | K5: MFA, Security Training | L5: Mitigate | M5: IAM Admin | N5: Open
A6: RSK-002 | B6: Web Application | C6: Application Security | D6: SQL injection could allow unauthorized database access | E6: SQL Injection | F6: Insufficient input validation | G6: 3 | H6: 5 | I6: =G6*H6 -> 15 | J6: =IF(I6>=17,"Critical",IF(I6>=10,"High",IF(I6>=5,"Medium","Low"))) -> High | K6: Secure Coding, Vulnerability Scanning | L6: Mitigate | M6: App Owner | N6: Open
A7: RSK-003 | B7: Cloud Infrastructure | C7: Cloud Security | D7: Cloud misconfiguration could expose sensitive resources | E7: Misconfiguration | F7: Excessive permissions | G7: 3 | H7: 5 | I7: =G7*H7 -> 15 | J7: =IF(I7>=17,"Critical",IF(I7>=10,"High",IF(I7>=5,"Medium","Low"))) -> High | K7: RBAC, Logging | L7: Mitigate | M7: Cloud Admin | N7: Open
A8: RSK-004 | B8: Employee Laptops | C8: Endpoint Security | D8: Ransomware could encrypt business data and disrupt operations | E8: Ransomware | F8: Inadequate endpoint controls | G8: 4 | H8: 4 | I8: =G8*H8 -> 16 | J8: =IF(I8>=17,"Critical",IF(I8>=10,"High",IF(I8>=5,"Medium","Low"))) -> High | K8: Endpoint Protection, Backup | L8: Mitigate | M8: IT Admin | N8: Open
A9: RSK-005 | B9: Employee Accounts | C9: Access Control | D9: Weak passwords could allow unauthorized account access | E9: Credential Attack | F9: Weak password practices | G9: 4 | H9: 4 | I9: =G9*H9 -> 16 | J9: =IF(I9>=17,"Critical",IF(I9>=10,"High",IF(I9>=5,"Medium","Low"))) -> High | K9: Password Policy | L9: Mitigate | M9: IAM Admin | N9: Open
A10: RSK-006 | B10: Customer Database | C10: Data Security | D10: Insider misuse could expose confidential customer information | E10: Insider Threat | F10: Excessive access privileges | G10: 3 | H10: 5 | I10: =G10*H10 -> 15 | J10: =IF(I10>=17,"Critical",IF(I10>=10,"High",IF(I10>=5,"Medium","Low"))) -> High | K10: RBAC, Access Reviews | L10: Mitigate | M10: Database Admin | N10: Open
A11: RSK-007 | B11: Backup System | C11: Business Continuity | D11: Backup failure could prevent recovery after data loss | E11: System Failure | F11: Inadequate recovery testing | G11: 3 | H11: 5 | I11: =G11*H11 -> 15 | J11: =IF(I11>=17,"Critical",IF(I11>=10,"High",IF(I11>=5,"Medium","Low"))) -> High | K11: Backup System | L11: Mitigate | M11: IT Admin | N11: Open
A12: RSK-008 | B12: Web Application | C12: Availability | D12: DDoS attack could disrupt payment services | E12: DDoS | F12: Limited traffic protection | G12: 3 | H12: 4 | I12: =G12*H12 -> 12 | J12: =IF(I12>=17,"Critical",IF(I12>=10,"High",IF(I12>=5,"Medium","Low"))) -> High | K12: Firewall | L12: Mitigate | M12: Network Admin | N12: Open
A13: RSK-009 | B13: Employee Laptops | C13: Endpoint Security | D13: Lost or stolen laptop could expose company information | E13: Device Loss | F13: Insufficient device encryption | G13: 3 | H13: 4 | I13: =G13*H13 -> 12 | J13: =IF(I13>=17,"Critical",IF(I13>=10,"High",IF(I13>=5,"Medium","Low"))) -> High | K13: Endpoint Protection | L13: Mitigate | M13: IT Admin | N13: Open
A14: RSK-010 | B14: Cloud Infrastructure | C14: Vulnerability Management | D14: Unpatched systems could be exploited by attackers | E14: Exploitation | F14: Delayed patching | G14: 4 | H14: 5 | I14: =G14*H14 -> 20 | J14: =IF(I14>=17,"Critical",IF(I14>=10,"High",IF(I14>=5,"Medium","Low"))) -> Critical | K14: Vulnerability Management | L14: Mitigate | M14: Cloud Admin | N14: Open
A15: RSK-011 | B15: Employee Accounts | C15: Access Control | D15: Excessive privileges could enable unauthorized access | E15: Privilege Abuse | F15: Poor access review | G15: 3 | H15: 4 | I15: =G15*H15 -> 12 | J15: =IF(I15>=17,"Critical",IF(I15>=10,"High",IF(I15>=5,"Medium","Low"))) -> High | K15: RBAC | L15: Mitigate | M15: IAM Admin | N15: In Progress
A16: RSK-012 | B16: Source Code Repository | C16: Application Security | D16: Repository compromise could expose source code and credentials | E16: Account Compromise | F16: Weak repository access controls | G16: 3 | H16: 5 | I16: =G16*H16 -> 15 | J16: =IF(I16>=17,"Critical",IF(I16>=10,"High",IF(I16>=5,"Medium","Low"))) -> High | K16: RBAC | L16: Mitigate | M16: Development Lead | N16: Open
... A19: RSK-015 | B19: Security Monitoring | C19: Incident Management | D19: Delayed detection could increase the impact of a security incident | E19: Cyberattack | F19: Incomplete monitoring | G19: 3 | H19: 4 | I19: =G19*H19 -> 12 | J19: =IF(I19>=17,"Critical",IF(I19>=10,"High",IF(I19>=5,"Medium","Low"))) -> High | K19: Logging & Monitoring | L19: Mitigate | M19: Security Team | N19: Open

Sheet Control Inventory
A1: SECUREPAY SOLUTIONS — CONTROL INVENTORY
A2: Simulated security control inventory for portfolio purposes.
A4: Control ID | B4: Control Name | C4: Control Type | D4: Description | E4: Owner | F4: Frequency | G4: Status
A5: CTRL-001 | B5: Multi-Factor Authentication | C5: Preventive | D5: Requires additional authentication factor for user access | E5: IAM Admin | F5: Continuous | G5: Partially Implemented
A6: CTRL-002 | B6: Role-Based Access Control | C6: Preventive | D6: Provides access based on defined user roles | E6: IAM Admin | F6: Continuous | G6: Implemented
A7: CTRL-003 | B7: Endpoint Protection | C7: Preventive/Detective | D7: Protects endpoints from malware and malicious activity | E7: IT Admin | F7: Continuous | G7: Implemented
A8: CTRL-004 | B8: Security Awareness Training | C8: Preventive | D8: Educates employees about security threats | E8: Security Team | F8: Annual | G8: Partially Implemented
A9: CTRL-005 | B9: Vulnerability Management | C9: Preventive | D9: Identifies and manages system vulnerabilities | E9: Security Team | F9: Monthly | G9: Partially Implemented
A10: CTRL-006 | B10: Data Backup | C10: Corrective | D10: Enables recovery of critical data following data loss | E10: IT Admin | F10: Daily | G10: Implemented
A11: CTRL-007 | B11: Firewall | C11: Preventive | D11: Controls network traffic between trusted and untrusted networks | E11: Network Admin | F11: Continuous | G11: Implemented
A12: CTRL-008 | B12: Logging & Monitoring | C12: Detective | D12: Collects and monitors security events | E12: Security Team | F12: Continuous | G12: Partially Implemented
A13: CTRL-009 | B13: Incident Response Plan | C13: Corrective | D13: Defines procedures for responding to security incidents | E13: Security Team | F13: Annual Review | G13: Partially Implemented
A14: CTRL-010 | B14: Access Reviews | C14: Detective | D14: Periodically reviews user permissions | E14: IAM Admin | F14: Quarterly | G14: Partially Implemented
A15: CTRL-011 | B15: Password Policy | C15: Preventive | D15: Defines password complexity and management requirements | E15: IAM Admin | F15: Annual Review | G15: Implemented
... A19: CTRL-015 | B19: Change Management | C19: Preventive | D19: Ensures changes are reviewed and authorized | E19: IT Manager | F19: Per Change | G19: Implemented

Sheet Risk-Control Mapping
A1: SECUREPAY SOLUTIONS — RISK-CONTROL MAPPING
A2: Mapping of identified risks to the controls that mitigate them.
A4: Risk ID | B4: Risk | C4: Control ID | D4: Control | E4: Control Status
A5: RSK-001 | B5: Phishing/account compromise | C5: CTRL-001 | D5: MFA | E5: Partially Implemented
A6: RSK-001 | B6: Phishing/account compromise | C6: CTRL-004 | D6: Security Awareness Training | E6: Partially Implemented
A7: RSK-002 | B7: SQL Injection | C7: CTRL-005 | D7: Vulnerability Management | E7: Partially Implemented
A8: RSK-002 | B8: SQL Injection | C8: CTRL-012 | D8: Secure Coding Practices | E8: Partially Implemented
A9: RSK-003 | B9: Cloud Misconfiguration | C9: CTRL-002 | D9: RBAC | E9: Implemented
A10: RSK-003 | B10: Cloud Misconfiguration | C10: CTRL-008 | D10: Logging & Monitoring | E10: Partially Implemented
A11: RSK-004 | B11: Ransomware | C11: CTRL-003 | D11: Endpoint Protection | E11: Implemented
A12: RSK-004 | B12: Ransomware | C12: CTRL-006 | D12: Data Backup | E12: Implemented
A13: RSK-005 | B13: Weak Passwords | C13: CTRL-001 | D13: MFA | E13: Partially Implemented
A14: RSK-005 | B14: Weak Passwords | C14: CTRL-011 | D14: Password Policy | E14: Implemented
A15: RSK-006 | B15: Insider Threat | C15: CTRL-002 | D15: RBAC | E15: Implemented
... A32: RSK-015 | B32: Delayed Detection | C32: CTRL-009 | D32: Incident Response Plan | E32: Partially Implemented

Sheet ISO 27001 Gap Assessment
A1: SECUREPAY SOLUTIONS — ISO 27001 GAP ASSESSMENT
A2: Simulated ISO/IEC 27001-based gap assessment for portfolio purposes (not an official certification audit).
A4: ID | B4: Control Area | C4: Requirement / Objective | D4: Current Status | E4: Gap Identified | F4: Recommendation | G4: Priority
A5: GAP-001 | B5: Information Security Policies | C5: Maintain documented security policies | D5: Implemented | E5: Minor documentation improvements required | F5: Review policies annually | G5: Medium
A6: GAP-002 | B6: Asset Management | C6: Maintain an inventory of information assets | D6: Implemented | E6: Review frequency needs formalization | F6: Perform quarterly asset reviews | G6: Medium
A7: GAP-003 | B7: Access Control | C7: Restrict access based on business requirements | D7: Partially Implemented | E7: Some excessive privileges identified | F7: Implement quarterly access reviews | G7: High
A8: GAP-004 | B8: Authentication | C8: Use appropriate authentication mechanisms | D8: Partially Implemented | E8: MFA not enabled for all users | F8: Implement MFA organization-wide | G8: Critical
A9: GAP-005 | B9: Security Awareness | C9: Provide security awareness training | D9: Partially Implemented | E9: Training not consistently documented | F9: Conduct and track annual training | G9: Medium
A10: GAP-006 | B10: Vulnerability Management | C10: Identify and address technical vulnerabilities | D10: Partially Implemented | E10: Vulnerability scanning process needs formalization | F10: Establish monthly scanning and remediation SLAs | G10: High
A11: GAP-007 | B11: Logging & Monitoring | C11: Monitor relevant security events | D11: Partially Implemented | E11: Centralized monitoring is limited | F11: Improve centralized logging and alerting | G11: High
A12: GAP-008 | B12: Incident Management | C12: Establish incident response processes | D12: Partially Implemented | E12: Incident response plan has not been tested | F12: Conduct tabletop exercises | G12: High
A13: GAP-009 | B13: Backup & Recovery | C13: Maintain appropriate backup capabilities | D13: Implemented | E13: Recovery testing requires stronger documentation | F13: Perform periodic restore testing | G13: High
A14: GAP-010 | B14: Secure Development | C14: Integrate security into development | D14: Partially Implemented | E14: Secure coding practices inconsistently documented | F14: Establish secure SDLC requirements | G14: High
A15: GAP-011 | B15: Device Security | C15: Protect organizational endpoint devices | D15: Partially Implemented | E15: Encryption coverage incomplete | F15: Enable encryption on all corporate laptops | G15: High
A16: GAP-012 | B16: Change Management | C16: Manage system changes appropriately | D16: Implemented | E16: Process exists but evidence retention can improve | F16: Maintain change approval records | G16: Medium

Sheet Remediation Plan
A1: SECUREPAY SOLUTIONS — REMEDIATION PLAN
A2: Remediation actions tracked against identified risks and compliance gaps.
A4: Finding ID | B4: Risk/Gap ID | C4: Finding | D4: Recommended Action | E4: Priority | F4: Owner | G4: Target | H4: Status
A5: REM-001 | B5: GAP-004 | C5: MFA coverage incomplete | D5: Enable MFA for all employee and privileged accounts | E5: Critical | F5: IAM Team | G5: 30 Days | H5: Open
A6: REM-002 | B6: GAP-003 | C6: Access reviews incomplete | D6: Conduct quarterly user access reviews | E6: High | F6: IAM Team | G6: 30 Days | H6: In Progress
A7: REM-003 | B7: GAP-006 | C7: Vulnerability management process needs formalization | D7: Establish monthly vulnerability scanning and remediation SLAs | E7: High | F7: Security Team | G7: 30 Days | H7: Open
A8: REM-004 | B8: GAP-007 | C8: Limited centralized monitoring | D8: Improve centralized logging and alerting | E8: High | F8: Security Team | G8: 60 Days | H8: Open
A9: REM-005 | B9: GAP-008 | C9: Incident response not tested | D9: Conduct an incident response tabletop exercise | E9: High | F9: Security Team | G9: 60 Days | H9: Open
A10: REM-006 | B10: GAP-010 | C10: Secure SDLC documentation incomplete | D10: Establish secure coding and security testing requirements | E10: High | F10: Development Lead | G10: 60 Days | H10: Open
A11: REM-007 | B11: GAP-011 | C11: Device encryption incomplete | D11: Enable encryption across corporate laptops | E11: High | F11: IT Team | G11: 45 Days | H11: Open
A12: REM-008 | B12: GAP-009 | C12: Recovery testing documentation incomplete | D12: Conduct and document backup restoration tests | E12: High | F12: IT Team | G12: 45 Days | H12: Open
A13: REM-009 | B13: GAP-005 | C13: Awareness training inconsistent | D13: Implement annual security awareness training | E13: Medium | F13: HR/Security | G13: 90 Days | H13: Open
A14: REM-010 | B14: GAP-002 | C14: Asset review frequency undefined | D14: Establish quarterly asset inventory review | E14: Medium | F14: IT Manager | G14: 90 Days | H14: Open

Sheet Evidence Register
A1: SECUREPAY SOLUTIONS — EVIDENCE REGISTER
A2: Simulated audit evidence supporting control implementation (no real company documents).
A4: Evidence ID | B4: Control ID | C4: Evidence Description | D4: Evidence Type | E4: Source | F4: Status | G4: Assessment Result
A5: EVD-001 | B5: CTRL-001 | C5: MFA configuration screenshot | D5: Screenshot | E5: Simulated | F5: Available | G5: Partial
A6: EVD-002 | B6: CTRL-002 | C6: RBAC role configuration | D6: Configuration Record | E6: Simulated | F6: Available | G6: Satisfactory
A7: EVD-003 | B7: CTRL-003 | C7: Endpoint protection status report | D7: Report | E7: Simulated | F7: Available | G7: Satisfactory
A8: EVD-004 | B8: CTRL-004 | C8: Security awareness training completion record | D8: Training Record | E8: Simulated | F8: Available | G8: Partial
A9: EVD-005 | B9: CTRL-005 | C9: Vulnerability scan report | D9: Security Report | E9: Simulated | F9: Available | G9: Partial
A10: EVD-006 | B10: CTRL-006 | C10: Backup job report | D10: System Report | E10: Simulated | F10: Available | G10: Satisfactory
A11: EVD-007 | B11: CTRL-007 | C11: Firewall configuration review | D11: Configuration Record | E11: Simulated | F11: Available | G11: Satisfactory
A12: EVD-008 | B12: CTRL-008 | C12: Security monitoring dashboard | D12: Screenshot | E12: Simulated | F12: Available | G12: Partial
A13: EVD-009 | B13: CTRL-009 | C13: Incident response plan | D13: Policy Document | E13: Simulated | F13: Available | G13: Partial
A14: EVD-010 | B14: CTRL-010 | C14: Quarterly access review | D14: Review Record | E14: Simulated | F14: Missing | G14: Gap Identified
A15: EVD-011 | B15: CTRL-011 | C15: Password policy document | D15: Policy Document | E15: Simulated | F15: Available | G15: Satisfactory
... A19: EVD-015 | B19: CTRL-015 | C19: Change approval record | D19: Change Record | E19: Simulated | F19: Available | G19: Satisfactory

Sheet Risk Matrix
A1: SECUREPAY SOLUTIONS — RISK MATRIX
A2: 5x5 Likelihood x Impact heat map (Risk Score = Likelihood x Impact). Shading reflects severity only, in grayscale.
A4: Impact ↓ / Likelihood → | B4: 1 | C4: 2 | D4: 3 | E4: 4 | F4: 5
A5: 5 - Severe | B5: 5 | C5: 10 RSK-014 | D5: 15 RSK-002, RSK-003, RSK-006, RSK-007, RSK-012 | E5: 20 RSK-001, RSK-010 | F5: 25
A6: 4 - Major | B6: 4 | C6: 8 | D6: 12 RSK-008, RSK-009, RSK-011, RSK-015 | E6: 16 RSK-004, RSK-005, RSK-013 | F6: 20 RSK-001, RSK-010
A7: 3 - Moderate | B7: 3 | C7: 6 | D7: 9 | E7: 12 RSK-008, RSK-009, RSK-011, RSK-015 | F7: 15 RSK-002, RSK-003, RSK-006, RSK-007, RSK-012
A8: 2 - Minor | B8: 2 | C8: 4 | D8: 6 | E8: 8 | F8: 10 RSK-014
A9: 1 - Insignificant | B9: 1 | C9: 2 | D9: 3 | E9: 4 | F9: 5
A12: SEVERITY LEGEND
A13: Critical (17-25) | B13: High (10-16) | C13: Medium (5-9) | D13: Low (1-4)
A15: Note: Cells combine the calculated Risk Score (Likelihood x Impact) with the Risk IDs from the Risk Register that fall at that score. Darker shading indicates a more severe risk score.
